Traceback (most recent call last):
  File "C:\Users\ezerof\neon_py\suave_sql\.venv\Lib\site-packages\jupyter_cache\executors\utils.py", line 58, in single_nb_execution
    executenb(
  File "C:\Users\ezerof\neon_py\suave_sql\.venv\Lib\site-packages\nbclient\client.py", line 1314, in execute
    return NotebookClient(nb=nb, resources=resources, km=km, **kwargs).execute()
           ^^^^^^^^^^^^^^^^^^^^^^^^^^^^^^^^^^^^^^^^^^^^^^^^^^^^^^^^^^^^^^^^^^^^^
  File "C:\Users\ezerof\neon_py\suave_sql\.venv\Lib\site-packages\jupyter_core\utils\__init__.py", line 165, in wrapped
    return loop.run_until_complete(inner)
           ^^^^^^^^^^^^^^^^^^^^^^^^^^^^^^
  File "C:\Users\ezerof\AppData\Local\Programs\Python\Python311\Lib\asyncio\base_events.py", line 653, in run_until_complete
    return future.result()
           ^^^^^^^^^^^^^^^
  File "C:\Users\ezerof\neon_py\suave_sql\.venv\Lib\site-packages\nbclient\client.py", line 709, in async_execute
    await self.async_execute_cell(
  File "C:\Users\ezerof\neon_py\suave_sql\.venv\Lib\site-packages\nbclient\client.py", line 1062, in async_execute_cell
    await self._check_raise_for_error(cell, cell_index, exec_reply)
  File "C:\Users\ezerof\neon_py\suave_sql\.venv\Lib\site-packages\nbclient\client.py", line 918, in _check_raise_for_error
    raise CellExecutionError.from_cell_and_msg(cell, exec_reply_content)
nbclient.exceptions.CellExecutionError: An error occurred while executing the following cell:
------------------
engine = create_engine('mysql+pymysql://eli:password@LCLCN001/neon', isolation_level="AUTOCOMMIT")
full_engine_settings = {
    'engine': engine,
    'print_SQL': True,
    'clipboard': False,
    'mycase': True,
    'default_table': 'stints.neon_chd'
}
------------------


[1;31m---------------------------------------------------------------------------[0m
[1;31mNameError[0m                                 Traceback (most recent call last)
Cell [1;32mIn[3], line 1[0m
[1;32m----> 1[0m engine [38;5;241m=[39m [43mcreate_engine[49m([38;5;124m'[39m[38;5;124mmysql+pymysql://eli:password@LCLCN001/neon[39m[38;5;124m'[39m, isolation_level[38;5;241m=[39m[38;5;124m"[39m[38;5;124mAUTOCOMMIT[39m[38;5;124m"[39m)
[0;32m      2[0m full_engine_settings [38;5;241m=[39m {
[0;32m      3[0m     [38;5;124m'[39m[38;5;124mengine[39m[38;5;124m'[39m: engine,
[0;32m      4[0m     [38;5;124m'[39m[38;5;124mprint_SQL[39m[38;5;124m'[39m: [38;5;28;01mTrue[39;00m,
[1;32m   (...)[0m
[0;32m      7[0m     [38;5;124m'[39m[38;5;124mdefault_table[39m[38;5;124m'[39m: [38;5;124m'[39m[38;5;124mstints.neon_chd[39m[38;5;124m'[39m
[0;32m      8[0m }

[1;31mNameError[0m: name 'create_engine' is not defined

